Workbook

Sheet LISEZ-MOI
B2: Fiche prop firm — fichier a remplir
B3: Aligne sur le gabarit HTML « Universal Prop Firm Page ». Un fichier par firme : la page se construit a partir de lui, et de rien d'autre.
B5: COMMENT REMPLIR
B6: Cellule jaune, texte bleu | C6: A remplir.
B7: Cellule gris-bleu, italique | C7: Exemple reel FuturesElite (7 sept. 2026). Remplace-le par ta firme.
B8: Cellule grise « (auto) » | C8: Calculee toute seule. Ne pas modifier.
B9: Liste deroulante | C9: Valeur imposee, pour que la meme chose s'ecrive toujours pareil.
B10: Cellule vide | C10: Carte d'identite et bande : la case affiche « — ». Ailleurs, l'emplacement disparait. Rien n'est invente.
B12: CE QUE CHAQUE ONGLET REMPLIT DANS LE HTML
B13: ConnuPour · Preuves | C13: Nouvelle page : « What [Firm] is known for » (4 faits) · chiffres sous la description
B14: Plateformes · OptionsAchat | C14: Nouvelle page : « Platforms » (selectionnables seulement) · etapes plateforme / data feed du configurateur
B15: Formation · ComptesApresReussite | C15: Nouvelle page : modules optionnels, absents si vides
B16: Firme | C16: Carte d'identite (logo, marche, nom, presentation, Founded, Country, CEO, type) · Bande : Tradable assets, Platforms, Payment methods, Trading profile
B17: Programmes · Plans · Phases | C17: « Account configurator » : les etapes, le prix, la selection · « Rules by phase » : le tableau Evaluation / Funded
B18: Offre | C18: Carte promo en haut (% OFF, code, mention) · Code et mention dans « Your selection »
B19: Conditions | C19: « Trading and payout conditions » : les cartes TRADING, COMMISSION, PAYOUTS
B20: Parcours | C20: « From evaluation to your first payout » : les etapes, dans l'ordre
B21: Couts | C21: Nouvelle page : carte FEES de « Trading and payout conditions » · ancienne page : « What you will actually pay »
B22: Regles | C22: Cartes Trading et Payouts : regles de conduite, filtrees par programme, taille et phase
B23: Verdict | C23: « PropFirmScanner verdict » : Our view, Best for, Things to know
B24: FAQ | C24: « Frequently asked questions » : les 5 questions du gabarit sont deja ecrites, il reste les reponses
B26: LES REGLES QUI EVITENT LES ERREURS
B27: Un plan, plusieurs phases | C27: Un plan = programme + variante + taille (onglet Plans). Ses phases Evaluation et Funded vont dans l'onglet Phases, une ligne chacune.
B28: Un seul plan dans la carte promo | C28: Mets « oui » dans plan_carte_promo sur UN seul plan : c'est lui qui s'affiche dans la carte en haut de page.
B29: Valeur inconnue | C29: Ecris un statut plutot que de laisser vide : not_published, not_applicable, needs_confirmation, source_conflict. Une cellule vide masque la ligne.
B30: Le JSON | C30: data/firms/<slug>.json est genere par scripts/xlsx_to_firm.py. On ne le modifie jamais a la main.
B31: Un code promo non confirme | C31: Si sa portee n'est pas confirmee, le prix remise s'affiche avec « ≈ » devant.
B33: CONTROLES AUTOMATIQUES | D33: attendu
B34: Programmes | C34: =COUNTA(Programmes!A3:A60) | D34: ≥ 1
B35: Plans (selections) | C35: =COUNTA(Plans!A3:A300) | D35: ≥ 1
B36: Phases | C36: =COUNTA(Phases!A3:A900) | D36: ≥ 1
B37: Plans dans la carte promo | C37: =COUNTIF(Plans!F3:F300,"oui") | D37: exactement 1
B38: Phases sans plan correspondant | C38: =COUNTIF(Phases!O3:O900,"PLAN INCONNU") | D38: 0
B39: Plans sans aucune phase | C39: =COUNTIF(Plans!L3:L300,"aucune phase") | D39: 0
B40: Plans d'un programme inconnu | C40: =COUNTIF(Plans!L3:L300,"programme inconnu") | D40: 0

Sheet Firme
A1: Champ | B1: Valeur a remplir | C1: Exemple — FuturesElite, 7 sept. 2026 | D1: Ou ca s'affiche dans le HTML · si vide
A2: slug | B2: the5ers | C2: futureselite | D2: N'est pas affiche : sert a l'adresse de la page et au lien sortant. Minuscules, sans espace. Obligatoire.
A3: nom | B3: The5ers | C3: FuturesElite | D3: Le titre de la carte d'identite, « Continue to [Firm] », le verdict et la FAQ. Obligatoire.
A4: logo_url | B4: https://the5ers.com/wp-content/uploads/2023/01/favicon.png | C4: https://www.google.com/s2/favicons?domain=futureselite.com&sz=128 | D4: Le logo, en tuile blanche. Il n'est pas cliquable : les sorties passent par Claim deal et Continue to. Vide : initiale du nom.
A5: trustpilot_score | B5: 4.7 | C5: 4.5 | D5: Hero, angle haut droit : note sur 5. Vide : le bloc Trustpilot n'apparait pas.
A6: trustpilot_review_count | B6: 38563 | C6: 1200 | D6: Nombre d'avis sous la note.
A7: trustpilot_url | B7: https://www.trustpilot.com/review/the5ers.com | C7: https://www.trustpilot.com/review/exemple.com | D7: Page Trustpilot de la firme : le badge y renvoie. Vide : badge non cliquable.
A8: marches | B8: cfd, futures | C8: futures | D8: « Firm type » (deduit d'ici) et le choix du marche dans le configurateur. futures, cfd — separes par une virgule si plusieurs.
A9: titre | B9: Ten years of funded trading, with no time limit | C9: Four routes to a funded futures account | D9: Nouvelle page : le H1, une proposition de valeur. Vide : le nom de la firme sert de H1.
A10: description | B10: Founded in 2016, The5ers is one of the oldest CFD prop firms still trading. No evaluation has a deadline, every CFD drawdown is static rather than trailing, and positions can be held overnight and over the weekend. Four routes, from $2,500 to instant funding, plus a futures line launched in 2026. | C10: Compare Elite, Nitro, Prime and Instant to choose between a traditional evaluation, a faster route or funding from purchase. | D10: Nouvelle page : 2 a 3 lignes sous le H1.
A11: resume | C11: Elite and Prime are evaluation routes with a one-time fee and no deadline to pass. Nitro and Instant shorten or remove the evaluation entirely, Instant funding you from purchase with no objective to reach. | D11: Ancienne page seulement (retour arriere) : 1 a 2 phrases sous le nom.
A12: presentation | B12: The5ers was founded in 2016 and trades as FIVE PERCENT ONLINE LTD, registered in Israel and in the United Kingdom. It is not regulated and does not provide financial services: it funds traders on its own capital, through commercial liquidity providers it does not name. The firm says it employs 171 people across 24 countries, has onboarded 262,000 traders and opened more than 1.6 million trading accounts. Four routes sit side by side. Pro Growth is a single evaluation phase. High Stakes is the two-step route, with the fee refunded in stages. Hyper Growth funds you from purchase and doubles the account at every 10% target. The futures line, launched separately, trades CME contracts on BlackArrow. | C12: FuturesElite sells simulated futures accounts across four programs. Elite and Prime are evaluation routes with a one-time fee and no deadline to pass. | D12: Section « About [Firm] » : texte developpe, paragraphes separes par une ligne vide (Alt+Entree deux fois).
A13: annee_creation | B13: 2016 | C13: 2024 | D13: « Founded ». Vide : « — ».
A14: pays | B14: Israel | C14: Italy | D14: « Country ».
A15: ceo_fondateur | B15: Gil Ben Hur | C15: Christian Habibi | D15: « CEO / Founder ». Vide : « — ».
A16: actifs | C16: Futures, Forex, Metals, Indices, Energy, Crypto, Bonds, Agricultural Products | D16: Ancienne page seulement : une etiquette par actif, separes par des virgules.
A17: categories_actifs | B17: Forex, Indices, Metals, Commodities, Crypto, Futures | C17: (vide — non confirmees) | D17: Nouvelle page, « Tradable assets » : categories precises (Index futures, Currency futures…), seulement si confirmees par la firme.
A18: categories_actifs_statut | B18: confirmed | C18: needs_confirmation | D18: confirmed si la liste est confirmee. Ou un statut : not_published (la firme ne le publie pas), not_applicable, needs_confirmation, source_conflict. Vide : la ligne disparait.
A19: plateformes | C19: Tradovate, NinjaTrader, Quantower, ATAS, WealthCharts, DeepChart, Volumetrica, DeepCharts | D19: Ancienne page seulement. La nouvelle lit l'onglet Plateformes.
A20: moyens_paiement | C20: Credit/Debit Card, Crypto | D20: « Purchase methods » : moyens de paiement A L'ACHAT, separes par des virgules.
A21: methodes_retrait | B21: Rise, Crypto, Bank transfer, Hub Credits | C21: Crypto, Riseworks | D21: Carte PAYOUTS : methodes de RETRAIT, separees par des virgules.
A22: prestataire_retrait | B22: Rise | C22: Rise | D22: Carte PAYOUTS : le prestataire qui paie les retraits.
A23: levier | C23: N/A (futures contracts) | D23: « Trading profile » : « Leverage 1:X ». Vide : « Leverage — ».
A24: levier_statut | C24: not_applicable | D24: Nouvelle page : confirmed si levier est rempli. Ou un statut : not_published (la firme ne le publie pas), not_applicable, needs_confirmation, source_conflict. Vide : la ligne disparait.
A25: styles_trading | B25: Day trading, Swing | C25: (vide — absent du releve) | D25: « Trading profile » : styles autorises (Swing…), separes par des virgules.
A26: meta_description | D26: Meta description de la page (Google). Vide : calculee depuis la presentation. 160 caracteres au plus.
A27: flux_donnees | D27: Carte « Data feeds » : flux de donnees proposes, separes par des virgules. Affichage seulement.

Sheet ConnuPour
A1: ordre | B1: titre | C1: detail
A2: 1 a 4. Quatre faits au plus : au-dela, ils sont ignores. | B2: Le fait, en quelques mots. Vrai pour toute la firme, pas pour un seul programme. | C2: La precision sous le fait.
A3: 1 | B3: Ten years in business | C3: Founded in 2016, 262,000 traders onboarded.
A4: 2 | B4: Fee refunded on High Stakes | C4: 10% after step 1, 20% after step 2, 70% in cash with your first payout.
A5: 3 | B5: Payouts every 14 days | C5: From $150 of profit, paid through Rise, crypto or bank transfer.
A6: 4 | B6: Scaling to $4,000,000 | C6: Hyper Growth doubles the account at every 10% target.

Sheet Preuves
A1: ordre | B1: libelle | C1: valeur | D1: source_url
A2: Ordre d'affichage. | B2: Ce que mesure le chiffre : « reviews », « traders funded in 2025 ». | C2: Le chiffre, tel qu'il s'affiche : « 4,900 ». | D2: Ou le chiffre a ete lu. Non affiche.

Sheet Plateformes
A1: nom | B1: selectionnable | C1: note | D1: logo_url
A2: Le nom officiel, ecrit une seule fois (pas deux orthographes). | B2: oui : choisie a l'achat, affichee. non : citee ailleurs par la firme, non affichee. | C2: Pourquoi, d'ou vient le nom. Non affiche. | D2: Icone officielle, prise sur le site de l'editeur (https). Vide : pastille a l'initiale.
A3: MetaTrader 5 | B3: oui | C3: CFD, hors Etats-Unis. | D3: https://www.metatrader5.com/i/favicons/apple-touch-icon-180x180.png
A4: cTrader | B4: oui | C4: CFD, hors Etats-Unis, +10 $. | D4: https://ctrader.com/favicon.ico
A5: TradingView | B5: oui | C5: CFD, seule plateforme proposee aux clients americains. | D5: https://static.tradingview.com/static/images/favicon/apple-touch-icon-180x180.png
A6: BlackArrow | B6: oui | C6: Seule plateforme des comptes futures.

Sheet Programmes
A1: slug | B1: nom | C1: marche | D1: type | E1: statut | F1: accroche | G1: resume | H1: max_comptes | I1: max_comptes_statut | J1: max_comptes_note | K1: nb_plans (auto) | L1: offre_fin | M1: offre_fin_statut
A2: Identifiant court, minuscules. Relie les plans et les phases. | B2: Carte « How do you want to be funded? ». | C2: Carte « Choose your market ». Masquee s'il n'y en a qu'un. | D2: instant = aucune evaluation : l'onglet Evaluation disparait. | E2: Seuls les « active » s'affichent. | F2: Petite phrase au-dessus du nom dans « How do you want to be funded? ». Vide : le type (Evaluation / No evaluation). | G2: Carte « Which program fits you? » : une phrase vraie de CE programme. Vide : la carte n'affiche que le nom. | H2: Comptes finances actifs au plus, pour CE programme. | I2: confirmed, ou un statut si le chiffre manque ou se contredit. | J2: La source, ou la contradiction. Affichee sous le chiffre. | K2: Plans rattaches. | L2: Campagne a duree limitee : sa date de fin. Vide si le programme est permanent. | M2: confirmed si la date est publiee. Sinon not_published, needs_confirmation ou source_conflict.
A3: high-stakes | B3: High Stakes | C3: cfd | D3: evaluation | E3: active | F3: The two-step route, fee refunded | G3: Challenge then Verification, a static loss limit and no deadline. The fee comes back in stages: 10% in Hub Credits after step 1, 20% after step 2, 70% in cash with your first payout. NEW asks 10% in step 1, Classic asks 8%. | H3: 4 | I3: confirmed | J3: Classic: one account per size. NEW: up to three on the small sizes. | K3: =IF(A3="","",COUNTIF(Plans!$A$3:$A$300,A3))
A4: pro-growth | B4: Pro Growth | C4: cfd | D4: evaluation | E4: active | F4: One phase, static drawdown | G4: A single evaluation phase: 10% target, a 6% static loss limit, a 3% daily loss and three profitable days worth at least 0.5% each. | H4: 4 | I4: source_conflict | J4: Two official articles disagree: three accounts on one page, four on another. | K4: =IF(A4="","",COUNTIF(Plans!$A$3:$A$300,A4))
A5: hyper-growth | B5: Hyper Growth | C5: cfd | D5: instant | E5: active | F5: Funded from purchase | G5: No evaluation at all. Hitting the daily limit pauses the account until midnight instead of closing it, and the balance doubles at every 10% target, up to $4,000,000. | H5: 4 | I5: confirmed | J5: Up to $40,000 of evaluation capital at a time. | K5: =IF(A5="","",COUNTIF(Plans!$A$3:$A$300,A5))
A6: bootcamp | B6: Bootcamp | C6: cfd | D6: evaluation | E6: active | F6: Three steps, growing balances | G6: The balance grows at each step instead of staying flat, with a 6% target every time and no daily loss until you are funded. A stop-loss is mandatory within three minutes of entry, risking at most 2%. | H6: 4 | I6: confirmed | J6: One $250K, one $100K and two $20K at a time. | K6: =IF(A6="","",COUNTIF(Plans!$A$3:$A$300,A6))
A7: summer-plan | B7: Summer Plan | C7: cfd | D7: evaluation | E7: limited_offer | F7: Campaign pricing, one or two steps | G7: The campaign catalogue: a one-step $100K and four two-step combinations on $100K and $200K, with a 50% daily consistency rule on the funded account and a payout cap the permanent programs do not have. | H7: 2 | I7: confirmed | J7: Two accounts on the $100K, one on the $200K. | K7: =IF(A7="","",COUNTIF(Plans!$A$3:$A$300,A7)) | M7: not_published
A8: futures | B8: Futures | C8: futures | D8: evaluation | E8: active | F8: CME contracts on BlackArrow | G8: A 6% target with a 4% end-of-day trailing drawdown, no minimum days, and a consistency rule of 40% per position. Day Trade closes everything before the session ends; Swing keeps one mini overnight. | H8: 5 | I8: confirmed | J8: Up to $500,000 across accounts: one $150K, two $100K, five small ones. | K8: =IF(A8="","",COUNTIF(Plans!$A$3:$A$300,A8))
K9: =IF(A9="","",COUNTIF(Plans!$A$3:$A$300,A9))
K10: =IF(A10="","",COUNTIF(Plans!$A$3:$A$300,A10))
K11: =IF(A11="","",COUNTIF(Plans!$A$3:$A$300,A11))
K12: =IF(A12="","",COUNTIF(Plans!$A$3:$A$300,A12))
K13: =IF(A13="","",COUNTIF(Plans!$A$3:$A$300,A13))
K14: =IF(A14="","",COUNTIF(Plans!$A$3:$A$300,A14))
K15: =IF(A15="","",COUNTIF(Plans!$A$3:$A$300,A15))
K16: =IF(A16="","",COUNTIF(Plans!$A$3:$A$300,A16))
K17: =IF(A17="","",COUNTIF(Plans!$A$3:$A$300,A17))
K18: =IF(A18="","",COUNTIF(Plans!$A$3:$A$300,A18))
K19: =IF(A19="","",COUNTIF(Plans!$A$3:$A$300,A19))
K20: =IF(A20="","",COUNTIF(Plans!$A$3:$A$300,A20))
... K23: =IF(A23="","",COUNTIF(Plans!$A$3:$A$300,A23))

Sheet Plans
A1: programme_slug | B1: taille | C1: variante | D1: devise | E1: prix | F1: plan_carte_promo | G1: facturation | H1: intervalle | I1: frais_reset | J1: frais_activation | K1: nb_phases (auto) | L1: controle (auto) | M1: lien_plan | N1: devise_compte
A2: Doit exister dans l'onglet Programmes. | B2: Bouton « 4. Choose an account size ». En chiffres. | C2: Bouton « 3. Choose a variant ». Vide si une seule variante. | D2: Devise du prix. | E2: Prix catalogue, sans remise : le prix barre de « Your selection ». | F2: oui sur UN seul plan : celui de la carte promo en haut de page. | G2: one_time (paiement unique) ou subscription (abonnement). | H2: monthly si abonnement : le prix s'affiche « /month ». | I2: Carte Fees : prix d'un reset apres une perte. Vide : ligne masquee. | J2: Carte Fees : frais pour activer le compte finance. 0 : « None ». | K2: Phases rattachees. | L2: ok, ou ce qui manque. | M2: Slug du plan dans prop_firm_challenges (voir DIAGNOSTIC-liens-plans). Les boutons ouvrent alors son lien profond : paiement de CE plan, code applique. Vide : lien general de la firme. | N2: Devise du SOLDE du compte : la taille, l'objectif et les limites. Vide : la devise du prix. A remplir quand la firme facture dans une monnaie et libelle les comptes dans une autre.
A3: high-stakes | B3: 2500 | C3: NEW | D3: USD | E3: 19 | G3: one_time | J3: 0 | K3: =IF(A3="","",SUMPRODUCT((Phases!$A$3:$A$900=A3)*(Phases!$B$3:$B$900=B3)*(Phases!$C$3:$C$900=C3))) | L3: =IF(A3="","",IF(COUNTIF(Programmes!$A$3:$A$60,A3)=0,"programme inconnu",IF(K3=0,"aucune phase","ok"))) | N3: USD
A4: high-stakes | B4: 5000 | C4: NEW | D4: USD | E4: 35 | G4: one_time | J4: 0 | K4: =IF(A4="","",SUMPRODUCT((Phases!$A$3:$A$900=A4)*(Phases!$B$3:$B$900=B4)*(Phases!$C$3:$C$900=C4))) | L4: =IF(A4="","",IF(COUNTIF(Programmes!$A$3:$A$60,A4)=0,"programme inconnu",IF(K4=0,"aucune phase","ok"))) | N4: USD
A5: high-stakes | B5: 10000 | C5: NEW | D5: USD | E5: 69 | G5: one_time | J5: 0 | K5: =IF(A5="","",SUMPRODUCT((Phases!$A$3:$A$900=A5)*(Phases!$B$3:$B$900=B5)*(Phases!$C$3:$C$900=C5))) | L5: =IF(A5="","",IF(COUNTIF(Programmes!$A$3:$A$60,A5)=0,"programme inconnu",IF(K5=0,"aucune phase","ok"))) | N5: USD
A6: high-stakes | B6: 25000 | C6: NEW | D6: USD | E6: 176 | G6: one_time | J6: 0 | K6: =IF(A6="","",SUMPRODUCT((Phases!$A$3:$A$900=A6)*(Phases!$B$3:$B$900=B6)*(Phases!$C$3:$C$900=C6))) | L6: =IF(A6="","",IF(COUNTIF(Programmes!$A$3:$A$60,A6)=0,"programme inconnu",IF(K6=0,"aucune phase","ok"))) | N6: USD
A7: high-stakes | B7: 50000 | C7: NEW | D7: USD | E7: 249 | G7: one_time | J7: 0 | K7: =IF(A7="","",SUMPRODUCT((Phases!$A$3:$A$900=A7)*(Phases!$B$3:$B$900=B7)*(Phases!$C$3:$C$900=C7))) | L7: =IF(A7="","",IF(COUNTIF(Programmes!$A$3:$A$60,A7)=0,"programme inconnu",IF(K7=0,"aucune phase","ok"))) | N7: USD
A8: high-stakes | B8: 100000 | C8: NEW | D8: USD | E8: 405 | F8: oui | G8: one_time | J8: 0 | K8: =IF(A8="","",SUMPRODUCT((Phases!$A$3:$A$900=A8)*(Phases!$B$3:$B$900=B8)*(Phases!$C$3:$C$900=C8))) | L8: =IF(A8="","",IF(COUNTIF(Programmes!$A$3:$A$60,A8)=0,"programme inconnu",IF(K8=0,"aucune phase","ok"))) | N8: USD
A9: high-stakes | B9: 2500 | C9: Classic | D9: USD | E9: 22 | G9: one_time | J9: 0 | K9: =IF(A9="","",SUMPRODUCT((Phases!$A$3:$A$900=A9)*(Phases!$B$3:$B$900=B9)*(Phases!$C$3:$C$900=C9))) | L9: =IF(A9="","",IF(COUNTIF(Programmes!$A$3:$A$60,A9)=0,"programme inconnu",IF(K9=0,"aucune phase","ok"))) | N9: USD
A10: high-stakes | B10: 5000 | C10: Classic | D10: USD | E10: 39 | G10: one_time | J10: 0 | K10: =IF(A10="","",SUMPRODUCT((Phases!$A$3:$A$900=A10)*(Phases!$B$3:$B$900=B10)*(Phases!$C$3:$C$900=C10))) | L10: =IF(A10="","",IF(COUNTIF(Programmes!$A$3:$A$60,A10)=0,"programme inconnu",IF(K10=0,"aucune phase","ok"))) | N10: USD
A11: high-stakes | B11: 10000 | C11: Classic | D11: USD | E11: 78 | G11: one_time | J11: 0 | K11: =IF(A11="","",SUMPRODUCT((Phases!$A$3:$A$900=A11)*(Phases!$B$3:$B$900=B11)*(Phases!$C$3:$C$900=C11))) | L11: =IF(A11="","",IF(COUNTIF(Programmes!$A$3:$A$60,A11)=0,"programme inconnu",IF(K11=0,"aucune phase","ok"))) | N11: USD
A12: high-stakes | B12: 25000 | C12: Classic | D12: USD | E12: 195 | G12: one_time | J12: 0 | K12: =IF(A12="","",SUMPRODUCT((Phases!$A$3:$A$900=A12)*(Phases!$B$3:$B$900=B12)*(Phases!$C$3:$C$900=C12))) | L12: =IF(A12="","",IF(COUNTIF(Programmes!$A$3:$A$60,A12)=0,"programme inconnu",IF(K12=0,"aucune phase","ok"))) | N12: USD
A13: high-stakes | B13: 50000 | C13: Classic | D13: USD | E13: 279 | G13: one_time | J13: 0 | K13: =IF(A13="","",SUMPRODUCT((Phases!$A$3:$A$900=A13)*(Phases!$B$3:$B$900=B13)*(Phases!$C$3:$C$900=C13))) | L13: =IF(A13="","",IF(COUNTIF(Programmes!$A$3:$A$60,A13)=0,"programme inconnu",IF(K13=0,"aucune phase","ok"))) | N13: USD
A14: high-stakes | B14: 100000 | C14: Classic | D14: USD | E14: 455 | G14: one_time | J14: 0 | K14: =IF(A14="","",SUMPRODUCT((Phases!$A$3:$A$900=A14)*(Phases!$B$3:$B$900=B14)*(Phases!$C$3:$C$900=C14))) | L14: =IF(A14="","",IF(COUNTIF(Programmes!$A$3:$A$60,A14)=0,"programme inconnu",IF(K14=0,"aucune phase","ok"))) | N14: USD
A15: pro-growth | B15: 5000 | D15: USD | E15: 52 | G15: one_time | J15: 0 | K15: =IF(A15="","",SUMPRODUCT((Phases!$A$3:$A$900=A15)*(Phases!$B$3:$B$900=B15)*(Phases!$C$3:$C$900=C15))) | L15: =IF(A15="","",IF(COUNTIF(Programmes!$A$3:$A$60,A15)=0,"programme inconnu",IF(K15=0,"aucune phase","ok"))) | N15: USD
A16: pro-growth | B16: 10000 | D16: USD | E16: 98 | G16: one_time | J16: 0 | K16: =IF(A16="","",SUMPRODUCT((Phases!$A$3:$A$900=A16)*(Phases!$B$3:$B$900=B16)*(Phases!$C$3:$C$900=C16))) | L16: =IF(A16="","",IF(COUNTIF(Programmes!$A$3:$A$60,A16)=0,"programme inconnu",IF(K16=0,"aucune phase","ok"))) | N16: USD
A17: pro-growth | B17: 20000 | D17: USD | E17: 189 | G17: one_time | J17: 0 | K17: =IF(A17="","",SUMPRODUCT((Phases!$A$3:$A$900=A17)*(Phases!$B$3:$B$900=B17)*(Phases!$C$3:$C$900=C17))) | L17: =IF(A17="","",IF(COUNTIF(Programmes!$A$3:$A$60,A17)=0,"programme inconnu",IF(K17=0,"aucune phase","ok"))) | N17: USD
A18: pro-growth | B18: 50000 | D18: USD | E18: 329 | G18: one_time | J18: 0 | K18: =IF(A18="","",SUMPRODUCT((Phases!$A$3:$A$900=A18)*(Phases!$B$3:$B$900=B18)*(Phases!$C$3:$C$900=C18))) | L18: =IF(A18="","",IF(COUNTIF(Programmes!$A$3:$A$60,A18)=0,"programme inconnu",IF(K18=0,"aucune phase","ok"))) | N18: USD
A19: hyper-growth | B19: 5000 | D19: USD | E19: 260 | G19: one_time | J19: 0 | K19: =IF(A19="","",SUMPRODUCT((Phases!$A$3:$A$900=A19)*(Phases!$B$3:$B$900=B19)*(Phases!$C$3:$C$900=C19))) | L19: =IF(A19="","",IF(COUNTIF(Programmes!$A$3:$A$60,A19)=0,"programme inconnu",IF(K19=0,"aucune phase","ok"))) | N19: USD
A20: hyper-growth | B20: 10000 | D20: USD | E20: 450 | G20: one_time | J20: 0 | K20: =IF(A20="","",SUMPRODUCT((Phases!$A$3:$A$900=A20)*(Phases!$B$3:$B$900=B20)*(Phases!$C$3:$C$900=C20))) | L20: =IF(A20="","",IF(COUNTIF(Programmes!$A$3:$A$60,A20)=0,"programme inconnu",IF(K20=0,"aucune phase","ok"))) | N20: USD
A21: hyper-growth | B21: 20000 | D21: USD | E21: 850 | G21: one_time | J21: 0 | K21: =IF(A21="","",SUMPRODUCT((Phases!$A$3:$A$900=A21)*(Phases!$B$3:$B$900=B21)*(Phases!$C$3:$C$900=C21))) | L21: =IF(A21="","",IF(COUNTIF(Programmes!$A$3:$A$60,A21)=0,"programme inconnu",IF(K21=0,"aucune phase","ok"))) | N21: USD
A22: bootcamp | B22: 20000 | D22: USD | E22: 22 | G22: one_time | J22: 0 | K22: =IF(A22="","",SUMPRODUCT((Phases!$A$3:$A$900=A22)*(Phases!$B$3:$B$900=B22)*(Phases!$C$3:$C$900=C22))) | L22: =IF(A22="","",IF(COUNTIF(Programmes!$A$3:$A$60,A22)=0,"programme inconnu",IF(K22=0,"aucune phase","ok"))) | N22: USD
A23: bootcamp | B23: 100000 | D23: USD | E23: 95 | G23: one_time | J23: 0 | K23: =IF(A23="","",SUMPRODUCT((Phases!$A$3:$A$900=A23)*(Phases!$B$3:$B$900=B23)*(Phases!$C$3:$C$900=C23))) | L23: =IF(A23="","",IF(COUNTIF(Programmes!$A$3:$A$60,A23)=0,"programme inconnu",IF(K23=0,"aucune phase","ok"))) | N23: USD
A24: bootcamp | B24: 250000 | D24: USD | E24: 225 | G24: one_time | J24: 0 | K24: =IF(A24="","",SUMPRODUCT((Phases!$A$3:$A$900=A24)*(Phases!$B$3:$B$900=B24)*(Phases!$C$3:$C$900=C24))) | L24: =IF(A24="","",IF(COUNTIF(Programmes!$A$3:$A$60,A24)=0,"programme inconnu",IF(K24=0,"aucune phase","ok"))) | N24: USD
A25: summer-plan | B25: 100000 | C25: 1-Step | D25: USD | E25: 249 | G25: one_time | J25: 0 | K25: =IF(A25="","",SUMPRODUCT((Phases!$A$3:$A$900=A25)*(Phases!$B$3:$B$900=B25)*(Phases!$C$3:$C$900=C25))) | L25: =IF(A25="","",IF(COUNTIF(Programmes!$A$3:$A$60,A25)=0,"programme inconnu",IF(K25=0,"aucune phase","ok"))) | N25: USD
A26: summer-plan | B26: 100000 | C26: 2-Step 10/5 | D26: USD | E26: 149 | G26: one_time | J26: 0 | K26: =IF(A26="","",SUMPRODUCT((Phases!$A$3:$A$900=A26)*(Phases!$B$3:$B$900=B26)*(Phases!$C$3:$C$900=C26))) | L26: =IF(A26="","",IF(COUNTIF(Programmes!$A$3:$A$60,A26)=0,"programme inconnu",IF(K26=0,"aucune phase","ok"))) | N26: USD
A27: summer-plan | B27: 100000 | C27: 2-Step 8/5 | D27: USD | E27: 179 | G27: one_time | J27: 0 | K27: =IF(A27="","",SUMPRODUCT((Phases!$A$3:$A$900=A27)*(Phases!$B$3:$B$900=B27)*(Phases!$C$3:$C$900=C27))) | L27: =IF(A27="","",IF(COUNTIF(Programmes!$A$3:$A$60,A27)=0,"programme inconnu",IF(K27=0,"aucune phase","ok"))) | N27: USD
A28: summer-plan | B28: 200000 | C28: 2-Step 10/5 | D28: USD | E28: 249 | G28: one_time | J28: 0 | K28: =IF(A28="","",SUMPRODUCT((Phases!$A$3:$A$900=A28)*(Phases!$B$3:$B$900=B28)*(Phases!$C$3:$C$900=C28))) | L28: =IF(A28="","",IF(COUNTIF(Programmes!$A$3:$A$60,A28)=0,"programme inconnu",IF(K28=0,"aucune phase","ok"))) | N28: USD
A29: summer-plan | B29: 200000 | C29: 2-Step 8/5 | D29: USD | E29: 279 | G29: one_time | J29: 0 | K29: =IF(A29="","",SUMPRODUCT((Phases!$A$3:$A$900=A29)*(Phases!$B$3:$B$900=B29)*(Phases!$C$3:$C$900=C29))) | L29: =IF(A29="","",IF(COUNTIF(Programmes!$A$3:$A$60,A29)=0,"programme inconnu",IF(K29=0,"aucune phase","ok"))) | N29: USD
A30: futures | B30: 25000 | C30: Day Trade | D30: USD | E30: 59 | G30: one_time | J30: 0 | K30: =IF(A30="","",SUMPRODUCT((Phases!$A$3:$A$900=A30)*(Phases!$B$3:$B$900=B30)*(Phases!$C$3:$C$900=C30))) | L30: =IF(A30="","",IF(COUNTIF(Programmes!$A$3:$A$60,A30)=0,"programme inconnu",IF(K30=0,"aucune phase","ok"))) | N30: USD
A31: futures | B31: 50000 | C31: Day Trade | D31: USD | E31: 100 | G31: one_time | J31: 0 | K31: =IF(A31="","",SUMPRODUCT((Phases!$A$3:$A$900=A31)*(Phases!$B$3:$B$900=B31)*(Phases!$C$3:$C$900=C31))) | L31: =IF(A31="","",IF(COUNTIF(Programmes!$A$3:$A$60,A31)=0,"programme inconnu",IF(K31=0,"aucune phase","ok"))) | N31: USD
A32: futures | B32: 100000 | C32: Day Trade | D32: USD | E32: 170 | G32: one_time | J32: 0 | K32: =IF(A32="","",SUMPRODUCT((Phases!$A$3:$A$900=A32)*(Phases!$B$3:$B$900=B32)*(Phases!$C$3:$C$900=C32))) | L32: =IF(A32="","",IF(COUNTIF(Programmes!$A$3:$A$60,A32)=0,"programme inconnu",IF(K32=0,"aucune phase","ok"))) | N32: USD
A33: futures | B33: 150000 | C33: Day Trade | D33: USD | E33: 199 | G33: one_time | J33: 0 | K33: =IF(A33="","",SUMPRODUCT((Phases!$A$3:$A$900=A33)*(Phases!$B$3:$B$900=B33)*(Phases!$C$3:$C$900=C33))) | L33: =IF(A33="","",IF(COUNTIF(Programmes!$A$3:$A$60,A33)=0,"programme inconnu",IF(K33=0,"aucune phase","ok"))) | N33: USD
A34: futures | B34: 25000 | C34: Swing | D34: USD | E34: 59 | G34: one_time | J34: 0 | K34: =IF(A34="","",SUMPRODUCT((Phases!$A$3:$A$900=A34)*(Phases!$B$3:$B$900=B34)*(Phases!$C$3:$C$900=C34))) | L34: =IF(A34="","",IF(COUNTIF(Programmes!$A$3:$A$60,A34)=0,"programme inconnu",IF(K34=0,"aucune phase","ok"))) | N34: USD
A35: futures | B35: 50000 | C35: Swing | D35: USD | E35: 100 | G35: one_time | J35: 0 | K35: =IF(A35="","",SUMPRODUCT((Phases!$A$3:$A$900=A35)*(Phases!$B$3:$B$900=B35)*(Phases!$C$3:$C$900=C35))) | L35: =IF(A35="","",IF(COUNTIF(Programmes!$A$3:$A$60,A35)=0,"programme inconnu",IF(K35=0,"aucune phase","ok"))) | N35: USD
A36: futures | B36: 100000 | C36: Swing | D36: USD | E36: 170 | G36: one_time | J36: 0 | K36: =IF(A36="","",SUMPRODUCT((Phases!$A$3:$A$900=A36)*(Phases!$B$3:$B$900=B36)*(Phases!$C$3:$C$900=C36))) | L36: =IF(A36="","",IF(COUNTIF(Programmes!$A$3:$A$60,A36)=0,"programme inconnu",IF(K36=0,"aucune phase","ok"))) | N36: USD
A37: futures | B37: 150000 | C37: Swing | D37: USD | E37: 199 | G37: one_time | J37: 0 | K37: =IF(A37="","",SUMPRODUCT((Phases!$A$3:$A$900=A37)*(Phases!$B$3:$B$900=B37)*(Phases!$C$3:$C$900=C37))) | L37: =IF(A37="","",IF(COUNTIF(Programmes!$A$3:$A$60,A37)=0,"programme inconnu",IF(K37=0,"aucune phase","ok"))) | N37: USD
K38: =IF(A38="","",SUMPRODUCT((Phases!$A$3:$A$900=A38)*(Phases!$B$3:$B$900=B38)*(Phases!$C$3:$C$900=C38))) | L38: =IF(A38="","",IF(COUNTIF(Programmes!$A$3:$A$60,A38)=0,"programme inconnu",IF(K38=0,"aucune phase","ok")))
K39: =IF(A39="","",SUMPRODUCT((Phases!$A$3:$A$900=A39)*(Phases!$B$3:$B$900=B39)*(Phases!$C$3:$C$900=C39))) | L39: =IF(A39="","",IF(COUNTIF(Programmes!$A$3:$A$60,A39)=0,"programme inconnu",IF(K39=0,"aucune phase","ok")))
K40: =IF(A40="","",SUMPRODUCT((Phases!$A$3:$A$900=A40)*(Phases!$B$3:$B$900=B40)*(Phases!$C$3:$C$900=C40))) | L40: =IF(A40="","",IF(COUNTIF(Programmes!$A$3:$A$60,A40)=0,"programme inconnu",IF(K40=0,"aucune phase","ok")))
...

Sheet Phases
A1: programme_slug | B1: taille | C1: variante | D1: phase | E1: objectif_profit | F1: perte_max | G1: type_perte_max | H1: perte_jour | I1: jours_min | J1: regularite | K1: max_contrats | L1: partage | M1: plafond_retrait | N1: retrait_minimum | O1: controle (auto) | P1: partage_bas | Q1: seuil_partage
A2: Le plan parent : programme… | B2: …taille… | C2: …et variante, comme dans Plans. | D2: Onglet Evaluation ou Funded. | E2: « Profit objective ». En devise. Vide en Funded. | F2: « Maximum loss » : la valeur… | G2: …et son type. | H2: « Daily loss ». En devise, ou « aucune », ou un statut (not_published…). Vide : ligne masquee. | I2: « Minimum days ». | J2: « Consistency ». En %, ou « aucune », ou « non confirmee ». | K2: « Maximum positions/contracts ». | L2: « Profit split ». En %. | M2: Funded : plafond par demande de retrait, en devise. Ou un statut : not_published (la firme ne le publie pas), not_applicable, needs_confirmation, source_conflict. Vide : la ligne disparait. | N2: Funded : minimum par demande, en devise. Ou un statut : not_published (la firme ne le publie pas), not_applicable, needs_confirmation, source_conflict. Vide : la ligne disparait. | O2: ok, ou plan introuvable. | P2: Partage par palier : le taux SOUS le seuil (50 %). Vide si un seul taux. Le taux au-dessus va dans « partage ». | Q2: Montant d'une demande de retrait a partir duquel « partage » s'applique. En devise. Avec partage_bas.
A3: high-stakes | B3: 2500 | C3: NEW | D3: evaluation | E3: 250 | F3: 250 | G3: Static | H3: 125 | I3: 3 | J3: aucune | O3: =IF(A3="","",IF(SUMPRODUCT((Plans!$A$3:$A$300=A3)*(Plans!$B$3:$B$300=B3)*(Plans!$C$3:$C$300=C3))=0,"PLAN INCONNU","ok"))
A4: high-stakes | B4: 2500 | C4: NEW | D4: evaluation_2 | E4: 125 | F4: 250 | G4: Static | H4: 125 | I4: 3 | J4: aucune | O4: =IF(A4="","",IF(SUMPRODUCT((Plans!$A$3:$A$300=A4)*(Plans!$B$3:$B$300=B4)*(Plans!$C$3:$C$300=C4))=0,"PLAN INCONNU","ok"))
A5: high-stakes | B5: 2500 | C5: NEW | D5: funded | F5: 250 | G5: Static | H5: 125 | I5: 3 | J5: aucune | L5: 0.8 | O5: =IF(A5="","",IF(SUMPRODUCT((Plans!$A$3:$A$300=A5)*(Plans!$B$3:$B$300=B5)*(Plans!$C$3:$C$300=C5))=0,"PLAN INCONNU","ok"))
A6: high-stakes | B6: 5000 | C6: NEW | D6: evaluation | E6: 500 | F6: 500 | G6: Static | H6: 250 | I6: 3 | J6: aucune | O6: =IF(A6="","",IF(SUMPRODUCT((Plans!$A$3:$A$300=A6)*(Plans!$B$3:$B$300=B6)*(Plans!$C$3:$C$300=C6))=0,"PLAN INCONNU","ok"))
A7: high-stakes | B7: 5000 | C7: NEW | D7: evaluation_2 | E7: 250 | F7: 500 | G7: Static | H7: 250 | I7: 3 | J7: aucune | O7: =IF(A7="","",IF(SUMPRODUCT((Plans!$A$3:$A$300=A7)*(Plans!$B$3:$B$300=B7)*(Plans!$C$3:$C$300=C7))=0,"PLAN INCONNU","ok"))
A8: high-stakes | B8: 5000 | C8: NEW | D8: funded | F8: 500 | G8: Static | H8: 250 | I8: 3 | J8: aucune | L8: 0.8 | O8: =IF(A8="","",IF(SUMPRODUCT((Plans!$A$3:$A$300=A8)*(Plans!$B$3:$B$300=B8)*(Plans!$C$3:$C$300=C8))=0,"PLAN INCONNU","ok"))
A9: high-stakes | B9: 10000 | C9: NEW | D9: evaluation | E9: 1000 | F9: 1000 | G9: Static | H9: 500 | I9: 3 | J9: aucune | O9: =IF(A9="","",IF(SUMPRODUCT((Plans!$A$3:$A$300=A9)*(Plans!$B$3:$B$300=B9)*(Plans!$C$3:$C$300=C9))=0,"PLAN INCONNU","ok"))
A10: high-stakes | B10: 10000 | C10: NEW | D10: evaluation_2 | E10: 500 | F10: 1000 | G10: Static | H10: 500 | I10: 3 | J10: aucune | O10: =IF(A10="","",IF(SUMPRODUCT((Plans!$A$3:$A$300=A10)*(Plans!$B$3:$B$300=B10)*(Plans!$C$3:$C$300=C10))=0,"PLAN INCONNU","ok"))
A11: high-stakes | B11: 10000 | C11: NEW | D11: funded | F11: 1000 | G11: Static | H11: 500 | I11: 3 | J11: aucune | L11: 0.8 | O11: =IF(A11="","",IF(SUMPRODUCT((Plans!$A$3:$A$300=A11)*(Plans!$B$3:$B$300=B11)*(Plans!$C$3:$C$300=C11))=0,"PLAN INCONNU","ok"))
A12: high-stakes | B12: 25000 | C12: NEW | D12: evaluation | E12: 2500 | F12: 2500 | G12: Static | H12: 1250 | I12: 3 | J12: aucune | O12: =IF(A12="","",IF(SUMPRODUCT((Plans!$A$3:$A$300=A12)*(Plans!$B$3:$B$300=B12)*(Plans!$C$3:$C$300=C12))=0,"PLAN INCONNU","ok"))
A13: high-stakes | B13: 25000 | C13: NEW | D13: evaluation_2 | E13: 1250 | F13: 2500 | G13: Static | H13: 1250 | I13: 3 | J13: aucune | O13: =IF(A13="","",IF(SUMPRODUCT((Plans!$A$3:$A$300=A13)*(Plans!$B$3:$B$300=B13)*(Plans!$C$3:$C$300=C13))=0,"PLAN INCONNU","ok"))
A14: high-stakes | B14: 25000 | C14: NEW | D14: funded | F14: 2500 | G14: Static | H14: 1250 | I14: 3 | J14: aucune | L14: 0.8 | O14: =IF(A14="","",IF(SUMPRODUCT((Plans!$A$3:$A$300=A14)*(Plans!$B$3:$B$300=B14)*(Plans!$C$3:$C$300=C14))=0,"PLAN INCONNU","ok"))
A15: high-stakes | B15: 50000 | C15: NEW | D15: evaluation | E15: 5000 | F15: 4000 | G15: Static | H15: 2000 | I15: 3 | J15: aucune | O15: =IF(A15="","",IF(SUMPRODUCT((Plans!$A$3:$A$300=A15)*(Plans!$B$3:$B$300=B15)*(Plans!$C$3:$C$300=C15))=0,"PLAN INCONNU","ok"))
A16: high-stakes | B16: 50000 | C16: NEW | D16: evaluation_2 | E16: 2500 | F16: 4000 | G16: Static | H16: 2000 | I16: 3 | J16: aucune | O16: =IF(A16="","",IF(SUMPRODUCT((Plans!$A$3:$A$300=A16)*(Plans!$B$3:$B$300=B16)*(Plans!$C$3:$C$300=C16))=0,"PLAN INCONNU","ok"))
A17: high-stakes | B17: 50000 | C17: NEW | D17: funded | F17: 4000 | G17: Static | H17: 2000 | I17: 3 | J17: aucune | L17: 0.8 | M17: 3000 | N17: 300 | O17: =IF(A17="","",IF(SUMPRODUCT((Plans!$A$3:$A$300=A17)*(Plans!$B$3:$B$300=B17)*(Plans!$C$3:$C$300=C17))=0,"PLAN INCONNU","ok"))
A18: high-stakes | B18: 100000 | C18: NEW | D18: evaluation | E18: 10000 | F18: 8000 | G18: Static | H18: 4000 | I18: 3 | J18: aucune | O18: =IF(A18="","",IF(SUMPRODUCT((Plans!$A$3:$A$300=A18)*(Plans!$B$3:$B$300=B18)*(Plans!$C$3:$C$300=C18))=0,"PLAN INCONNU","ok"))
A19: high-stakes | B19: 100000 | C19: NEW | D19: evaluation_2 | E19: 5000 | F19: 8000 | G19: Static | H19: 4000 | I19: 3 | J19: aucune | O19: =IF(A19="","",IF(SUMPRODUCT((Plans!$A$3:$A$300=A19)*(Plans!$B$3:$B$300=B19)*(Plans!$C$3:$C$300=C19))=0,"PLAN INCONNU","ok"))
A20: high-stakes | B20: 100000 | C20: NEW | D20: funded | F20: 8000 | G20: Static | H20: 4000 | I20: 3 | J20: aucune | L20: 0.8 | M20: 4000 | N20: 500 | O20: =IF(A20="","",IF(SUMPRODUCT((Plans!$A$3:$A$300=A20)*(Plans!$B$3:$B$300=B20)*(Plans!$C$3:$C$300=C20))=0,"PLAN INCONNU","ok"))
A21: high-stakes | B21: 2500 | C21: Classic | D21: evaluation | E21: 200 | F21: 250 | G21: Static | H21: 125 | I21: 3 | J21: aucune | O21: =IF(A21="","",IF(SUMPRODUCT((Plans!$A$3:$A$300=A21)*(Plans!$B$3:$B$300=B21)*(Plans!$C$3:$C$300=C21))=0,"PLAN INCONNU","ok"))
A22: high-stakes | B22: 2500 | C22: Classic | D22: evaluation_2 | E22: 125 | F22: 250 | G22: Static | H22: 125 | I22: 3 | J22: aucune | O22: =IF(A22="","",IF(SUMPRODUCT((Plans!$A$3:$A$300=A22)*(Plans!$B$3:$B$300=B22)*(Plans!$C$3:$C$300=C22))=0,"PLAN INCONNU","ok"))
A23: high-stakes | B23: 2500 | C23: Classic | D23: funded | F23: 250 | G23: Static | H23: 125 | I23: 3 | J23: aucune | L23: 0.8 | O23: =IF(A23="","",IF(SUMPRODUCT((Plans!$A$3:$A$300=A23)*(Plans!$B$3:$B$300=B23)*(Plans!$C$3:$C$300=C23))=0,"PLAN INCONNU","ok"))
A24: high-stakes | B24: 5000 | C24: Classic | D24: evaluation | E24: 400 | F24: 500 | G24: Static | H24: 250 | I24: 3 | J24: aucune | O24: =IF(A24="","",IF(SUMPRODUCT((Plans!$A$3:$A$300=A24)*(Plans!$B$3:$B$300=B24)*(Plans!$C$3:$C$300=C24))=0,"PLAN INCONNU","ok"))
A25: high-stakes | B25: 5000 | C25: Classic | D25: evaluation_2 | E25: 250 | F25: 500 | G25: Static | H25: 250 | I25: 3 | J25: aucune | O25: =IF(A25="","",IF(SUMPRODUCT((Plans!$A$3:$A$300=A25)*(Plans!$B$3:$B$300=B25)*(Plans!$C$3:$C$300=C25))=0,"PLAN INCONNU","ok"))
A26: high-stakes | B26: 5000 | C26: Classic | D26: funded | F26: 500 | G26: Static | H26: 250 | I26: 3 | J26: aucune | L26: 0.8 | O26: =IF(A26="","",IF(SUMPRODUCT((Plans!$A$3:$A$300=A26)*(Plans!$B$3:$B$300=B26)*(Plans!$C$3:$C$300=C26))=0,"PLAN INCONNU","ok"))
A27: high-stakes | B27: 10000 | C27: Classic | D27: evaluation | E27: 800 | F27: 1000 | G27: Static | H27: 500 | I27: 3 | J27: aucune | O27: =IF(A27="","",IF(SUMPRODUCT((Plans!$A$3:$A$300=A27)*(Plans!$B$3:$B$300=B27)*(Plans!$C$3:$C$300=C27))=0,"PLAN INCONNU","ok"))
A28: high-stakes | B28: 10000 | C28: Classic | D28: evaluation_2 | E28: 500 | F28: 1000 | G28: Static | H28: 500 | I28: 3 | J28: aucune | O28: =IF(A28="","",IF(SUMPRODUCT((Plans!$A$3:$A$300=A28)*(Plans!$B$3:$B$300=B28)*(Plans!$C$3:$C$300=C28))=0,"PLAN INCONNU","ok"))
A29: high-stakes | B29: 10000 | C29: Classic | D29: funded | F29: 1000 | G29: Static | H29: 500 | I29: 3 | J29: aucune | L29: 0.8 | O29: =IF(A29="","",IF(SUMPRODUCT((Plans!$A$3:$A$300=A29)*(Plans!$B$3:$B$300=B29)*(Plans!$C$3:$C$300=C29))=0,"PLAN INCONNU","ok"))
A30: high-stakes | B30: 25000 | C30: Classic | D30: evaluation | E30: 2000 | F30: 2500 | G30: Static | H30: 1250 | I30: 3 | J30: aucune | O30: =IF(A30="","",IF(SUMPRODUCT((Plans!$A$3:$A$300=A30)*(Plans!$B$3:$B$300=B30)*(Plans!$C$3:$C$300=C30))=0,"PLAN INCONNU","ok"))
A31: high-stakes | B31: 25000 | C31: Classic | D31: evaluation_2 | E31: 1250 | F31: 2500 | G31: Static | H31: 1250 | I31: 3 | J31: aucune | O31: =IF(A31="","",IF(SUMPRODUCT((Plans!$A$3:$A$300=A31)*(Plans!$B$3:$B$300=B31)*(Plans!$C$3:$C$300=C31))=0,"PLAN INCONNU","ok"))
A32: high-stakes | B32: 25000 | C32: Classic | D32: funded | F32: 2500 | G32: Static | H32: 1250 | I32: 3 | J32: aucune | L32: 0.8 | O32: =IF(A32="","",IF(SUMPRODUCT((Plans!$A$3:$A$300=A32)*(Plans!$B$3:$B$300=B32)*(Plans!$C$3:$C$300=C32))=0,"PLAN INCONNU","ok"))
A33: high-stakes | B33: 50000 | C33: Classic | D33: evaluation | E33: 4000 | F33: 4000 | G33: Static | H33: 2000 | I33: 3 | J33: aucune | O33: =IF(A33="","",IF(SUMPRODUCT((Plans!$A$3:$A$300=A33)*(Plans!$B$3:$B$300=B33)*(Plans!$C$3:$C$300=C33))=0,"PLAN INCONNU","ok"))
A34: high-stakes | B34: 50000 | C34: Classic | D34: evaluation_2 | E34: 2500 | F34: 4000 | G34: Static | H34: 2000 | I34: 3 | J34: aucune | O34: =IF(A34="","",IF(SUMPRODUCT((Plans!$A$3:$A$300=A34)*(Plans!$B$3:$B$300=B34)*(Plans!$C$3:$C$300=C34))=0,"PLAN INCONNU","ok"))
A35: high-stakes | B35: 50000 | C35: Classic | D35: funded | F35: 4000 | G35: Static | H35: 2000 | I35: 3 | J35: aucune | L35: 0.8 | M35: 3000 | N35: 300 | O35: =IF(A35="","",IF(SUMPRODUCT((Plans!$A$3:$A$300=A35)*(Plans!$B$3:$B$300=B35)*(Plans!$C$3:$C$300=C35))=0,"PLAN INCONNU","ok"))
A36: high-stakes | B36: 100000 | C36: Classic | D36: evaluation | E36: 8000 | F36: 8000 | G36: Static | H36: 4000 | I36: 3 | J36: aucune | O36: =IF(A36="","",IF(SUMPRODUCT((Plans!$A$3:$A$300=A36)*(Plans!$B$3:$B$300=B36)*(Plans!$C$3:$C$300=C36))=0,"PLAN INCONNU","ok"))
A37: high-stakes | B37: 100000 | C37: Classic | D37: evaluation_2 | E37: 5000 | F37: 8000 | G37: Static | H37: 4000 | I37: 3 | J37: aucune | O37: =IF(A37="","",IF(SUMPRODUCT((Plans!$A$3:$A$300=A37)*(Plans!$B$3:$B$300=B37)*(Plans!$C$3:$C$300=C37))=0,"PLAN INCONNU","ok"))
A38: high-stakes | B38: 100000 | C38: Classic | D38: funded | F38: 8000 | G38: Static | H38: 4000 | I38: 3 | J38: aucune | L38: 0.8 | M38: 4000 | N38: 500 | O38: =IF(A38="","",IF(SUMPRODUCT((Plans!$A$3:$A$300=A38)*(Plans!$B$3:$B$300=B38)*(Plans!$C$3:$C$300=C38))=0,"PLAN INCONNU","ok"))
A39: pro-growth | B39: 5000 | D39: evaluation | E39: 500 | F39: 300 | G39: Static | H39: 150 | I39: 3 | J39: aucune | O39: =IF(A39="","",IF(SUMPRODUCT((Plans!$A$3:$A$300=A39)*(Plans!$B$3:$B$300=B39)*(Plans!$C$3:$C$300=C39))=0,"PLAN INCONNU","ok"))
A40: pro-growth | B40: 5000 | D40: funded | F40: 300 | G40: Static | H40: 150 | I40: 0 | J40: aucune | L40: 0.75 | N40: 150 | O40: =IF(A40="","",IF(SUMPRODUCT((Plans!$A$3:$A$300=A40)*(Plans!$B$3:$B$300=B40)*(Plans!$C$3:$C$300=C40))=0,"PLAN INCONNU","ok"))
...

Sheet OptionsAchat
A1: type | B1: nom | C1: detail | D1: parametre | E1: valeur | F1: programmes | G1: logo_url
A2: plateforme ou data_feed. Une etape du configurateur par type, seulement s'il y a au moins deux options. | B2: Le nom du bouton. | C2: La ligne sous le nom. | D2: Le nom du parametre transmis au paiement (opt_key). Lettres, chiffres, tirets. | E2: Sa valeur (opt_value). | F2: Slugs concernes, separes par des virgules. Vide : tous les programmes. | G2: Icone officielle de l'option, prise sur le site de l'editeur (https). Vide : logo de la plateforme du meme nom, sinon initiale.

Sheet Offre
A1: Champ | B1: Valeur a remplir | C1: Exemple — FuturesElite, 7 sept. 2026 | D1: Ou ca s'affiche dans le HTML · si vide
A2: code | C2: SCANNED | D2: La case pointillee « [CODE] », en haut et dans « Your selection ».
A3: remise | C3: 0.3 | D3: « [XX]% OFF » et « [XX]% with [CODE] ». En %.
A4: portee | C4: non_confirmee | D4: non_confirmee → prix remise affiche avec « ≈ ». Sert aussi la reponse FAQ sur le code.
A5: checkout_verifie | C5: non | D5: oui seulement si le paiement a ete teste avec le code.
A6: programmes_eligibles | C6: (vide — non confirme) | D6: Le prix remise ne s'affiche que sur ces programmes, et la reponse FAQ « Does the promotional code apply to every account? ». Slugs separes par des virgules.
A7: tailles_eligibles | C7: (vide — non confirme) | D7: Idem, pour les tailles.
A8: expire_le | C8: (vide — date de fin inconnue) | D8: Non affiche sur la page pour l'instant.
A9: statut | B9: needs_confirmation | C9: needs_confirmation | D9: Seule une offre confirmed s'affiche : remise, code, Copy code et Claim deal. Vide ou needs_confirmation : la carte garde le plan, le prix public et Continue to.

Sheet Conditions
A1: Champ | B1: Valeur a remplir | C1: Exemple — FuturesElite, 7 sept. 2026 | D1: Ou ca s'affiche dans le HTML · si vide
A2: trading | C2: Overnight holding is not allowed; automatic liquidation may occur. Market closed Friday 16:55 EST to Sunday 18:00 EST. Fully automated AI or bots are not permitted. The configurator lists scalping as not allowed, without defining it. News trading is allowed in evaluation and restricted once funded, without a stated event window. | D2: Carte TRADING : actifs, levier par actif, news, week-end, overnight, EA, scalping.
A3: commission | C3: Commissions and exchange fees are charged per instrument on each executed trade. | D3: Carte COMMISSION : commission par lot ou contrat, spreads, frais de donnees.
A4: retraits | C4: Payout requests are reviewed in under 24 hours on average. Provider: Rise. KYC via Veriff: buyer, KYC holder and account operator must be the same person. Elite 25K funded: 90% split, $1,000 cap per request, $500 minimum. | D4: Carte PAYOUTS : premier retrait, frequence, minimum, plafond, partage, prestataire, KYC.

Sheet Parcours
A1: ordre | B1: etape | C1: titre | D1: texte
A2: 1, 2, 3 : l'ordre des etapes, de gauche a droite. | B2: evaluation, funded ou payout. Sert le petit titre au-dessus de l'etape. | C2: Le titre de l'etape, en quelques mots. | D2: Ce qui se passe a cette etape, au niveau de la firme. Les differences entre programmes restent dans « Which program fits you? ».
A3: 1 | B3: evaluation | C3: Evaluation | D3: One phase on Pro Growth and on futures, two on High Stakes, none on Hyper Growth. No time limit, and no monthly fee.
A4: 2 | B4: funded | C4: Pro Trader account | D4: You trade the same limits with no profit target. KYC is required once you pass: identity and proof of address.
A5: 3 | B5: payout | C5: Payouts | D5: The first payout comes 14 days after the funded account opens, then every 14 days. Withdrawals carry a 3.5% fee, or none in Hub Credits.

Sheet Formation
A1: type | B1: ordre | C1: texte
A2: titre, intro ou element. | B2: Ordre des elements. | C2: Le texte. Sans aucune ligne : le module n'existe pas.

Sheet ComptesApresReussite
A1: compte | B1: description | C1: ordre | D1: libelle | E1: valeur
A2: Le nom du compte. Plusieurs lignes par compte. | B2: Une phrase, sur la premiere ligne du compte. | C2: Ordre des lignes du compte. | D2: La caracteristique : « Access », « Drawdown ». | E2: Sa valeur.

Sheet Couts
A1: ordre | B1: libelle | C1: montant | D1: note | E1: programmes
A2: 1, 2, 3 : l'ordre des lignes. | B2: Le nom du frais, tel qu'il s'affiche. | C2: Texte libre : « $95 – $569 », « None », « Per contract ». Vide : la ligne affiche « — ». | D2: Quand il se paie, et a quelle condition. Vide : rien sous le montant. | E2: Slugs concernes, separes par des virgules. Vide : tous. Le prix, le reset et l'activation sont dans Plans.
A3: 1 | B3: Evaluation fee | C3: One-time | D3: Paid once, at purchase. No monthly fee and no activation fee.
A4: 2 | B4: Balance at funding | C4: $50 to $350 | D4: The Bootcamp is paid in two parts: the entry fee above, then the balance when you reach the funded account — $50 on the $20K, $205 on the $100K, $350 on the $250K. | E4: bootcamp
A5: 3 | B5: Platform surcharge | C5: $10 | D5: Added when you pick cTrader instead of MetaTrader 5 or TradingView. | E5: high-stakes, pro-growth, hyper-growth, bootcamp, summer-plan
A6: 4 | B6: Withdrawal fee | C6: 3.5% | D6: On Rise, crypto and bank transfers. Hub Credits carry no fee but cannot be withdrawn: they only buy new accounts, and expire after three months.
A7: 5 | B7: Commissions | C7: Per trade | D7: CFD: $4 per forex lot round turn, nothing on indices, a percentage on metals, oil and crypto. Futures: $5.00 round turn on standard contracts, $2.50 on micros.

Sheet Regles
A1: carte | B1: regle | C1: texte | D1: statut | E1: programmes | F1: tailles | G1: phase | H1: bloquante | I1: essentielle | J1: source_url | K1: variantes
A2: trading, payouts, ou live (programme de compte reel, replie sous Payouts). | B2: Le nom court de la regle : « Overnight holding ». | C2: Ce que dit la firme, sans reformuler au-dela. | D2: confirmed, not_published, not_applicable, needs_confirmation ou source_conflict. | E2: Slugs concernes, separes par des virgules. Vide : tous. | F2: Tailles concernees (25000, 50000…). Vide : toutes. | G2: evaluation, evaluation_2 ou funded. Vide : toutes les phases. | H2: oui si l'enfreindre fait perdre le compte. | I2: oui : affichee sur la page. Les autres restent dans le tableur sans s'afficher. Quatre par carte au plus. | J2: Page officielle. Non affichee. | K2: Variantes concernees (Day Trade, Swing, NEW...), separees par des virgules. Vide : toutes.
A3: trading | B3: Daily loss | C3: Measured at 00:00 server time on the higher of the previous balance or equity. Hitting it closes the account. | D3: confirmed | E3: high-stakes, pro-growth, summer-plan | H3: oui | I3: oui | J3: https://the5ers.com/faqs/what-is-the-drawdown-rule-for-high-stakes/
A4: trading | B4: Daily pause | C4: Hitting the daily limit does not close the account: it is disabled until 00:00 MT5 server time, and you trade again the next day. | D4: confirmed | E4: hyper-growth, bootcamp | G4: funded | I4: oui | J4: https://the5ers.com/faqs/how-does-the-daily-pause-work/
A5: trading | B5: Daily loss | C5: None during the three evaluation steps. The 3% limit only applies once you are funded, and it pauses the account rather than closing it. | D5: confirmed | E5: bootcamp | G5: evaluation | I5: oui | J5: https://the5ers.com/bootcamp/
A6: trading | B6: Maximum loss | C6: Static: measured against the starting balance, and it never trails your profits. | D6: confirmed | E6: high-stakes, pro-growth, hyper-growth, bootcamp, summer-plan | H6: oui | I6: oui | J6: https://the5ers.com/faqs/what-is-the-drawdown-rule-for-high-stakes/
A7: trading | B7: Maximum loss | C7: Trailing on the highest midnight balance or equity, not on the starting balance. | D7: confirmed | E7: futures | H7: oui | I7: oui | J7: https://the5ers.com/futures-faqs/what-is-my-maximum-drawdown-loss/
A8: trading | B8: Profitable days | C8: A day counts when closed positions gain at least 0.5% of the starting balance. | D8: needs_confirmation | E8: high-stakes, pro-growth | I8: oui | J8: https://the5ers.com/high-stakes/
A9: trading | B9: Stop-loss | C9: Mandatory, placed within three minutes of entry, risking at most 2% of the balance on a position. | D9: confirmed | E9: bootcamp | H9: oui | I9: oui | J9: https://the5ers.com/bootcamp/
A10: trading | B10: Consistency | C10: Your best day may not carry more than 50% of the total profit once funded. | D10: confirmed | E10: summer-plan | G10: funded | I10: oui | J10: https://the5ers.com/summer-plan/
A11: trading | B11: Consistency | C11: One position may not carry more than 40% of the total profit. | D11: confirmed | E11: futures | I11: oui | J11: https://the5ers.com/futures/
A12: trading | B12: Consistency | C12: Not published for this program. The firm states only that the percentage varies by account type and region. | D12: not_published | E12: high-stakes, pro-growth, hyper-growth, bootcamp | J12: https://the5ers.com/faqs/
A13: trading | B13: Time limit | C13: None: no evaluation has a deadline. | D13: confirmed | G13: evaluation | I13: oui | J13: https://the5ers.com/high-stakes/
A14: trading | B14: Instruments | C14: Forex, metals, indices, energy and crypto, as CFDs. | D14: confirmed | E14: high-stakes, pro-growth, hyper-growth, bootcamp, summer-plan | I14: oui | J14: https://the5ers.com/faqs/what-instruments-can-i-trade/
A15: trading | B15: Instruments | C15: CME futures, in mini and micro contracts. | D15: confirmed | E15: futures | I15: oui | J15: https://the5ers.com/futures/
A16: trading | B16: Trading hours | C16: Forex and crypto 00:05-23:55 EET; metals, indices and commodities 01:05-23:50. Crypto is the only market open at the weekend. | D16: confirmed | E16: high-stakes, pro-growth, hyper-growth, bootcamp, summer-plan | J16: https://the5ers.com/faqs/market-trading-hours/
A17: trading | B17: Trading hours | C17: Sunday 17:00 CT to Friday 16:00 CT, with a maintenance break from 16:00 to 17:00 CT. | D17: confirmed | E17: futures | I17: oui | J17: https://the5ers.com/futures-faqs/futures-market-hours/
A18: trading | B18: Overnight and weekend | C18: Allowed on every CFD program. Holding indices over the weekend is permitted, with higher swaps. | D18: confirmed | E18: high-stakes, pro-growth, hyper-growth, bootcamp, summer-plan | I18: oui | J18: https://the5ers.com/faqs/do-i-have-to-close-my-positions-overnight/
A19: trading | B19: Overnight and weekend | C19: Everything must be closed before 16:50 CT. Nothing is held overnight or over the weekend. | D19: confirmed | E19: futures | H19: oui | I19: oui | J19: https://the5ers.com/futures-faqs/overnight-holding-2/ | K19: Day Trade
A20: trading | B20: Overnight and weekend | C20: Up to one mini or ten micros may be held overnight, and the position must be reduced before 16:50 CT. Nothing is held over the weekend. | D20: confirmed | E20: futures | H20: oui | I20: oui | J20: https://the5ers.com/futures-faqs/overnight-holding-2/ | K20: Swing
A21: trading | B21: News trading | C21: Allowed, but no order may be executed from two minutes before to two minutes after a high-impact release. Profits made in that window are removed; losses stay. | D21: confirmed | E21: high-stakes, summer-plan | H21: oui | I21: oui | J21: https://the5ers.com/faqs/can-i-trade-during-news/
A22: trading | B22: News trading | C22: Allowed, except strategies that bracket the release. | D22: confirmed | E22: pro-growth, hyper-growth, bootcamp | I22: oui | J22: https://the5ers.com/faqs/can-i-trade-during-news/
A23: trading | B23: News trading | C23: Allowed. | D23: confirmed | E23: futures | I23: oui | J23: https://the5ers.com/futures/
A24: trading | B24: Expert advisors | C24: Allowed when you own the source code. Copied signals, tick scalping, latency or hedge arbitrage, HFT and emulators are not. A hidden stop-loss is a breach. | D24: confirmed | E24: high-stakes, pro-growth, hyper-growth, bootcamp, summer-plan | H24: oui | I24: oui | J24: https://the5ers.com/faqs/can-i-use-an-ea-expert-advisor-can-i-set-a-stealth-mode-stop-loss/
A25: trading | B25: Expert advisors | C25: High-frequency trading, algorithmic trading and hedging are not allowed. | D25: confirmed | E25: futures | H25: oui | I25: oui | J25: https://the5ers.com/futures-faqs/is-high-frequency-algorithmic-trading-and-hedging-allowed/
A26: trading | B26: Copy trading | C26: You may copy your own trades between your own accounts. Copying someone else's is a breach. | D26: confirmed | H26: oui | I26: oui | J26: https://the5ers.com/faqs/can-i-copy-my-own-trades/
A27: trading | B27: Leverage | C27: 1:100 on forex, 1:25 on indices and metals, 1:5 on commodities, 1:2 on crypto. | D27: confirmed | E27: high-stakes | I27: oui | J27: https://the5ers.com/faqs/what-is-the-leverage-in-the-high-stakes-program/
A28: trading | B28: Leverage | C28: 1:30 on forex, 1:25 on indices and metals, 1:1.5 on commodities, 1:0.6 on crypto. | D28: confirmed | E28: pro-growth, hyper-growth, bootcamp | I28: oui | J28: https://the5ers.com/faqs/what-is-the-leverage-in-the-progrowth-program/
A29: trading | B29: Leverage | C29: 1:100 overall. The firm does not publish a figure per asset class for this campaign. | D29: not_published | E29: summer-plan | I29: oui | J29: https://the5ers.com/summer-plan/
A30: trading | B30: Leverage | C30: None: futures are traded in contracts, not on leverage. | D30: not_applicable | E30: futures | J30: https://the5ers.com/futures/
A31: trading | B31: Platforms | C31: MetaTrader 5, cTrader (+$10) or TradingView. US clients are offered TradingView only, and the choice is final once you buy. | D31: confirmed | E31: high-stakes, pro-growth, hyper-growth, bootcamp, summer-plan | I31: oui | J31: https://the5ers.com/faqs/which-trading-platform-do-you-use/
A32: trading | B32: Platforms | C32: BlackArrow only, on Windows, macOS, iOS, Android and the browser. | D32: confirmed | E32: futures | I32: oui | J32: https://the5ers.com/futures-faqs/what-trading-platform-can-i-use-with-the5ers-futures/
A33: trading | B33: Inactivity | C33: 30 days without a trade during the evaluation, 60 days once funded. | D33: confirmed | E33: high-stakes, pro-growth, hyper-growth, bootcamp, summer-plan | H33: oui | J33: https://the5ers.com/faqs/prohibited-trading-practices/
A34: trading | B34: Inactivity | C34: 14 calendar days without a trade. | D34: confirmed | E34: futures | H34: oui | J34: https://the5ers.com/faqs/prohibited-trading-practices/
A35: payouts | B35: Payout schedule | C35: The first payout comes 14 days after the funded account opens, then every 14 days. The clock restarts at each scaling step. | D35: confirmed | G35: funded | I35: oui | J35: https://the5ers.com/faqs/withdrawals-everything-you-need-to-know/
A36: payouts | B36: Minimum withdrawal | C36: $150 of profit as a rule; $300 on the $50K and $500 on the $100K. | D36: confirmed | E36: high-stakes | G36: funded | I36: oui | J36: https://the5ers.com/faqs/withdrawals-everything-you-need-to-know/
A37: payouts | B37: Minimum withdrawal | C37: $250, and the payout is capped per request. | D37: confirmed | E37: summer-plan | G37: funded | I37: oui | J37: https://the5ers.com/summer-plan/
A38: payouts | B38: Minimum withdrawal | C38: 4% of the starting balance, on an account at least 14 days old. | D38: confirmed | E38: futures | G38: funded | I38: oui | J38: https://the5ers.com/futures-faqs/what-do-i-need-for-a-withdrawal/
A39: payouts | B39: Minimum withdrawal | C39: Not published for this program. | D39: not_published | E39: pro-growth, hyper-growth, bootcamp | G39: funded | J39: https://the5ers.com/faqs/withdrawals-everything-you-need-to-know/
A40: payouts | B40: Withdrawal methods | C40: Rise, crypto or bank transfer, each with a 3.5% fee. Crypto is capped at $1,500 per withdrawal. Hub Credits carry no fee but only buy accounts. | D40: confirmed | G40: funded | I40: oui | J40: https://the5ers.com/faqs/withdrawals-everything-you-need-to-know/
...

Sheet Verdict
A1: type | B1: ordre | C1: texte
A2: Un seul bloc « PropFirmScanner verdict » : verdict = « Our view » (1 ligne) · pour_qui = « Best for » · limite = « Things to know » | B2: 1, 2, 3 dans chaque type. Le gabarit en montre 3. | C2: Conclusion independante, sans superlatif marketing.
A3: verdict | B3: 1 | C3: Ten years in business, and the range best suited to swing trading: no deadline on any evaluation, a static drawdown instead of a trailing one, positions held overnight and over the weekend, and scaling that runs into the millions. Entry tickets start at $19, among the lowest on the market, and the catalogue covers every budget from $2,500 to $250,000 of capital. In exchange, every withdrawal costs 3.5%, the news window on High Stakes is strict to the minute, and the firm states plainly that it is not regulated and that the accounts are simulated.
A4: pour_qui | B4: 1 | C4: Swing traders: overnight and weekend positions stay allowed on the CFD programs.
A5: pour_qui | B5: 2 | C5: Traders who take their time: no evaluation has a deadline.
A6: pour_qui | B6: 3 | C6: Small budgets: from $19 for a $2,500 account.
A7: pour_qui | B7: 4 | C7: Traders who prefer a static drawdown to a trailing one.
A8: limite | B8: 1 | C8: Every withdrawal carries a 3.5% fee, whatever the method.
A9: limite | B9: 2 | C9: On High Stakes, placing an order two minutes around a high-impact release is a breach.
A10: limite | B10: 3 | C10: The split varies widely: 50% on Hyper Growth, 75% on Pro Growth, 80% on High Stakes.

Sheet FAQ
A1: ordre | B1: question | C1: reponse
A2: Ordre d'affichage. | B2: Les 5 questions du gabarit sont pre-remplies ; [Firm] sera remplace par le nom. Tu peux en ajouter. | C2: Vide : la page recompose la reponse depuis les autres onglets (programmes, prix, partage, retraits, offre).
A3: 1 | B3: Is [Firm] suitable for beginners?
A4: 2 | B4: How much does [Firm] cost?
A5: 3 | B5: What profit split does [Firm] offer?
A6: 4 | B6: How do payouts work?
A7: 5 | B7: Does the promotional code apply to every account?

Sheet Listes
A1: statut_valeur | B1: facturation | C1: intervalle | D1: type_option | E1: type_formation | F1: etape_parcours | G1: marche | H1: type_programme | I1: statut | J1: phase | K1: type_perte | L1: devise | M1: portee_offre | N1: oui_non | O1: type_verdict | P1: carte_regle | Q1: phase_regle
A2: confirmed | B2: one_time | C2: monthly | D2: plateforme | E2: titre | F2: evaluation | G2: futures | H2: evaluation | I2: active | J2: evaluation | K2: End of Day | L2: USD | M2: universelle_verifiee | N2: oui | O2: verdict | P2: trading | Q2: evaluation
A3: not_published | B3: subscription | D3: data_feed | E3: intro | F3: funded | G3: cfd | H3: instant | I3: promotional | J3: evaluation_2 | K3: Trailing Equity | L3: EUR | M3: restreinte | N3: non | O3: pour_qui | P3: payouts | Q3: evaluation_2
A4: not_applicable | E4: element | F4: payout | G4: stocks | I4: retired | J4: funded | K4: Trailing Intraday | L4: GBP | M4: non_confirmee | O4: limite | P4: live | Q4: funded
A5: needs_confirmation | F5: certification | G5: crypto | K5: Static
A6: source_conflict
